{"uuid": "6213a262-5528-4e3e-ba33-50f2b7e81869", "children": ["22ca7967-5b5b-4f39-ba58-79950512b7d5"], "befores": [{"name": "driver", "status": "broken", "statusDetails": {"message": "Exception: 创建WebDriver实例失败: __init__() got an unexpected keyword argument 'path'\n", "trace": "  File \"D:\\Python39\\lib\\site-packages\\pluggy\\_callers.py\", line 167, in _multicall\n    teardown.throw(outcome._exception)\n  File \"D:\\Python39\\lib\\site-packages\\_pytest\\setuponly.py\", line 36, in pytest_fixture_setup\n    return (yield)\n  File \"D:\\Python39\\lib\\site-packages\\pluggy\\_callers.py\", line 103, in _multicall\n    res = hook_impl.function(*args)\n  File \"D:\\Python39\\lib\\site-packages\\_pytest\\fixtures.py\", line 1140, in pytest_fixture_setup\n    result = call_fixture_func(fixturefunc, request, kwargs)\n  File \"D:\\Python39\\lib\\site-packages\\_pytest\\fixtures.py\", line 891, in call_fixture_func\n    fixture_result = next(generator)\n  File \"E:\\AutoTest\\FgAI\\conftest.py\", line 56, in driver\n    driver = DriverManager.get_driver()\n  File \"E:\\AutoTest\\FgAI\\common\\driver_manager.py\", line 101, in get_driver\n    raise Exception(error_msg)\n"}, "start": 1742889976242, "stop": 1742889976243}], "start": 1742889976242, "stop": 1742889976316}