INFO     automation:conftest.py:55 开始初始化WebDriver...
INFO     automation:driver_manager.py:30 开始创建Chrome WebDriver实例...
INFO     automation:driver_manager.py:52 使用本地 ChromeDriver: E:\AutoTest\FgAI\chromedriver-win64\chromedriver.exe
INFO     automation:driver_manager.py:61 Chrome WebDriver 创建成功
INFO     automation:conftest.py:61 WebDriver实例验证成功
INFO     automation:test_UserCenter.py:40 开始执行个人中心测试
INFO     automation:test_UserCenter.py:54 开始执行登录...
INFO     automation:login_page.py:181 成功打开登录页面
INFO     automation:login_page.py:118 开始输入用户名: wxdfg
INFO     automation:login_page.py:125 用户名输入完成
INFO     automation:login_page.py:130 开始输入密码
INFO     automation:login_page.py:137 密码输入完成
INFO     automation:login_page.py:79 ==================================================
INFO     automation:login_page.py:80 请在弹出窗口中输入验证码
INFO     automation:login_page.py:81 ==================================================
INFO     automation:login_page.py:93 验证码已自动填入
INFO     automation:login_page.py:146 尝试点击登录按钮
INFO     automation:login_page.py:157 登录按钮点击成功
INFO     automation:login_page.py:162 等待用户信息元素出现
ERROR    automation:login_page.py:28 登录超时，未检测到用户信息
ERROR    automation:login_page.py:28 登录过程失败: 登录超时，未检测到用户信息
WARNING  urllib3.connectionpool:connectionpool.py:812 Retrying (Retry(total=2, connect=None, read=None, redirect=None, status=None)) after connection broken by 'NewConnectionError('<urllib3.connection.HTTPConnection object at 0x000002225F943850>: Failed to establish a new connection: [WinError 10061] 由于目标计算机积极拒绝，无法连接。')': /session/9ad2e87629dbaa8dd64c10cc72d805d5/screenshot
WARNING  urllib3.connectionpool:connectionpool.py:812 Retrying (Retry(total=1, connect=None, read=None, redirect=None, status=None)) after connection broken by 'NewConnectionError('<urllib3.connection.HTTPConnection object at 0x000002225F943880>: Failed to establish a new connection: [WinError 10061] 由于目标计算机积极拒绝，无法连接。')': /session/9ad2e87629dbaa8dd64c10cc72d805d5/screenshot
WARNING  urllib3.connectionpool:connectionpool.py:812 Retrying (Retry(total=0, connect=None, read=None, redirect=None, status=None)) after connection broken by 'NewConnectionError('<urllib3.connection.HTTPConnection object at 0x000002225F943A30>: Failed to establish a new connection: [WinError 10061] 由于目标计算机积极拒绝，无法连接。')': /session/9ad2e87629dbaa8dd64c10cc72d805d5/screenshot
ERROR    automation:login_page.py:37 无法截图
ERROR    automation:test_UserCenter.py:91 个人中心测试流程失败: 登录过程失败: 登录超时，未检测到用户信息
WARNING  urllib3.connectionpool:connectionpool.py:812 Retrying (Retry(total=2, connect=None, read=None, redirect=None, status=None)) after connection broken by 'NewConnectionError('<urllib3.connection.HTTPConnection object at 0x000002225F943D30>: Failed to establish a new connection: [WinError 10061] 由于目标计算机积极拒绝，无法连接。')': /session/9ad2e87629dbaa8dd64c10cc72d805d5/screenshot
WARNING  urllib3.connectionpool:connectionpool.py:812 Retrying (Retry(total=1, connect=None, read=None, redirect=None, status=None)) after connection broken by 'NewConnectionError('<urllib3.connection.HTTPConnection object at 0x000002225F943F40>: Failed to establish a new connection: [WinError 10061] 由于目标计算机积极拒绝，无法连接。')': /session/9ad2e87629dbaa8dd64c10cc72d805d5/screenshot
WARNING  urllib3.connectionpool:connectionpool.py:812 Retrying (Retry(total=0, connect=None, read=None, redirect=None, status=None)) after connection broken by 'NewConnectionError('<urllib3.connection.HTTPConnection object at 0x0000022265D2D130>: Failed to establish a new connection: [WinError 10061] 由于目标计算机积极拒绝，无法连接。')': /session/9ad2e87629dbaa8dd64c10cc72d805d5/screenshot
INFO     automation:test_UserCenter.py:42 个人中心测试执行完成