{"uuid": "ecd08df2-2bb9-41f0-84e8-83e0a0b1d9f0", "children": ["0e3d0677-b550-49a7-88df-769a4f357ab0"], "befores": [{"name": "driver", "status": "broken", "statusDetails": {"message": "selenium.common.exceptions.SessionNotCreatedException: Message: session not created: probably user data directory is already in use, please specify a unique value for --user-data-dir argument, or don't use --user-data-dir\nStacktrace:\n\tGetHandleVerifier [0x0095C7F3+24435]\n\t(No symbol) [0x008E2074]\n\t(No symbol) [0x007B06E3]\n\t(No symbol) [0x007E35E8]\n\t(No symbol) [0x007DF3E9]\n\t(No symbol) [0x00829686]\n\t(No symbol) [0x008290BA]\n\t(No symbol) [0x0081D5B6]\n\t(No symbol) [0x007EC54F]\n\t(No symbol) [0x007ED894]\n\tGetHandleVerifier [0x00C670A3+3213347]\n\tGetHandleVerifier [0x00C7B0C9+3295305]\n\tGetHandleVerifier [0x00C7558C+3271948]\n\tGetHandleVerifier [0x009F7360+658144]\n\t(No symbol) [0x008EB27D]\n\t(No symbol) [0x008E8208]\n\t(No symbol) [0x008E83A9]\n\t(No symbol) [0x008DAAC0]\n\tBaseThreadInitThunk [0x75005D49+25]\n\tRtlInitializeExceptionChain [0x7726CE3B+107]\n\tRtlGetAppContainerNamedObjectPath [0x7726CDC1+561]\n\n", "trace": "  File \"D:\\Python39\\lib\\site-packages\\pluggy\\_callers.py\", line 167, in _multicall\n    teardown.throw(outcome._exception)\n  File \"D:\\Python39\\lib\\site-packages\\_pytest\\setuponly.py\", line 36, in pytest_fixture_setup\n    return (yield)\n  File \"D:\\Python39\\lib\\site-packages\\pluggy\\_callers.py\", line 103, in _multicall\n    res = hook_impl.function(*args)\n  File \"D:\\Python39\\lib\\site-packages\\_pytest\\fixtures.py\", line 1140, in pytest_fixture_setup\n    result = call_fixture_func(fixturefunc, request, kwargs)\n  File \"D:\\Python39\\lib\\site-packages\\_pytest\\fixtures.py\", line 891, in call_fixture_func\n    fixture_result = next(generator)\n  File \"E:\\AutoTest\\FgAI\\conftest.py\", line 61, in driver\n    driver = DriverManager.get_driver()\n  File \"E:\\AutoTest\\FgAI\\common\\driver_manager.py\", line 45, in get_driver\n    cls._driver = webdriver.Chrome(service=service, options=chrome_options)\n  File \"D:\\Python39\\lib\\site-packages\\selenium\\webdriver\\chrome\\webdriver.py\", line 45, in __init__\n    super().__init__(\n  File \"D:\\Python39\\lib\\site-packages\\selenium\\webdriver\\chromium\\webdriver.py\", line 66, in __init__\n    super().__init__(command_executor=executor, options=options)\n  File \"D:\\Python39\\lib\\site-packages\\selenium\\webdriver\\remote\\webdriver.py\", line 250, in __init__\n    self.start_session(capabilities)\n  File \"D:\\Python39\\lib\\site-packages\\selenium\\webdriver\\remote\\webdriver.py\", line 342, in start_session\n    response = self.execute(Command.NEW_SESSION, caps)[\"value\"]\n  File \"D:\\Python39\\lib\\site-packages\\selenium\\webdriver\\remote\\webdriver.py\", line 429, in execute\n    self.error_handler.check_response(response)\n  File \"D:\\Python39\\lib\\site-packages\\selenium\\webdriver\\remote\\errorhandler.py\", line 232, in check_response\n    raise exception_class(message, screen, stacktrace)\n"}, "start": 1742959589621, "stop": 1742959599214}], "start": 1742959589621, "stop": 1742959599553}